Workbook

Sheet Company_Selection
A1: Company | B1: Ticker | C1: Category | D1: Why selected | E1: Main AI monetization angle | F1: Priority (1-6) | G1: Include?
A2: Microsoft | B2: MSFT | C2: Cloud / Productivity | D2: Scale + clear AI monetization across Azure and Copilot | E2: Add-on pricing + usage-based cloud consumption | F2: 1 | G2: Yes
A3: Salesforce | B3: CRM | C3: CRM / Workflow | D3: Strong agentic AI / digital labor thesis | E3: AI add-on + upsell within installed base | F3: 2 | G3: Yes
A4: Adobe | B4: ADBE | C4: Creative / Document Software | D4: Good revenue mix shift case via Firefly / credits | E4: Credits + premium subscription mix | F4: 3 | G4: Yes
A5: ServiceNow | B5: NOW | C5: Workflow / Automation | D5: Enterprise workflow AI upsell opportunity | E5: AI workflow upsell + platform expansion | F5: 4 | G5: Yes
A6: Intuit | B6: INTU | C6: SMB / Financial Software | D6: Differentiated finance workflow AI case | E6: Higher ARPC / service bundle monetization | F6: 5 | G6: Yes
A7: Palantir | B7: PLTR | C7: AI Platform | D7: Clear AIP platform deployment story | E7: Platform expansion + enterprise adoption | F7: 6 | G7: Yes

Sheet Raw_Data
A1: Company | B1: Ticker | C1: Fiscal_Year | D1: Revenue_2025_USD_Bn | E1: Operating_Income_2025_USD_Bn | F1: Existing_AI_Revenue_Share_2025_% | G1: Segment_1_Name | H1: Segment_1_Revenue_USD_Bn | I1: Segment_2_Name | J1: Segment_2_Revenue_USD_Bn | K1: Segment_3_Name | L1: Segment_3_Revenue_USD_Bn | M1: Main_AI_Products | N1: AI_Monetization_Model | O1: Recent_AI_Proxy | P1: Primary_Source_URL | Q1: Secondary_Source_URL | R1: Notes
A2: Microsoft | B2: MSFT | C2: FY2025 | D2: 281.724 | E2: 128.528 | F2: 0.046144453 | G2: Productivity and Business Processes | H2: 120.81 | I2: Intelligent Cloud | J2: 106.265 | K2: More Personal Computing | L2: 54.649 | M2: Azure AI; Microsoft 365 Copilot; GitHub Copilot; Dynamics 365 Copilot | N2: Usage-based cloud consumption; seat-based add-on/premium upsell | O2: AI run-rate >$13B; Azure growth included 13 pts from AI services in FY25 Q2 | P2: https://www.microsoft.com/investor/reports/ar25/index.html | Q2: https://www.microsoft.com/en-us/investor/events/fy-2025/earnings-fy-2025-q2 | R2: AI revenue share is a proxy based on the >$13B AI annual run rate disclosed in FY25 Q2, not a reported FY2025 AI revenue line.
A3: Salesforce | B3: CRM | C3: FY2025 | D3: 37.895 | E3: 7.2 | F3: 0.023749835 | G3: Service | H3: 9.054 | I3: Sales | J3: 8.322 | K3: Platform and Other | L3: 7.247 | M3: Agentforce; Data Cloud; Einstein | N3: ARR add-on; platform upsell; cross-sell into Customer 360 | O3: $900M Data Cloud & AI ARR; 5,000 Agentforce deals, including >3,000 paid | P3: https://s205.q4cdn.com/626266368/files/doc_financials/2025/ar/Salesforce-FY25-Annual-Report.pdf | Q3: https://investor.salesforce.com/news/news-details/2025/Salesforce-Announces-Fourth-Quarter-and-Fiscal-Year-2025-Results/default.aspx | R3: Salesforce reports one operating segment; top 3 subscription & support service offerings are shown here. AI revenue share is a proxy based on Data Cloud & AI ARR / FY25 revenue.
A4: Adobe | B4: ADBE | C4: FY2025 | D4: 23.769 | E4: 8.71 | G4: Digital Media | H4: 17.649 | I4: Digital Experience | J4: 5.864 | K4: Publishing and Advertising | L4: 0.256 | M4: Firefly; Acrobat AI Assistant; GenStudio | N4: Tiered Firefly subscriptions; generative credits; premium upsell | O4: FY2025 delivered significant AI-influenced and AI-first ending ARR; Firefly sold via Standard/Pro/Premium plans | P4: https://www.adobe.com/cc-shared/assets/investor-relations/pdfs/adbe-10k-fy25-final.pdf | Q4: https://www.adobe.com/cc-shared/assets/investor-relations/pdfs/01215202/a54gu6y5tegrrf.pdf | R4: No directly disclosed FY2025 AI revenue share; percent field left blank. Adobe will move to one segment in FY2026.
A5: ServiceNow | B5: NOW | C5: FY2024 | D5: 10.984 | E5: 1.364 | F5: 0.018208303 | G5: Subscription revenues | H5: 10.646 | I5: Professional services and other | J5: 0.338 | M5: Now Assist; AI Agent Orchestrator; AI Agent Studio; Pro Plus AI | N5: Pro Plus / Enterprise Plus upsell; platform subscription expansion | O5: GenAI net new ACV stepped up in Q4; Now Assist service desk deals +150% QoQ; Pro Plus AI ACV >$200M; nearly 1,000 AI customers | P5: https://newsroom.servicenow.com/press-releases/details/2025/ServiceNow-Reports-Fourth-Quarter-and-Full-Year-2024-Financial-Results-01-29-2025-traffic/default.aspx | Q5: https://newsroom.servicenow.com/press-releases/details/2025/ServiceNow-to-extend-leading-agentic-AI-to-every-employee-for-every-corner-of-the-business-with-acquisition-of-Moveworks-03-10-2025-traffic/default.aspx | R5: ServiceNow's latest full-year data publicly available here is FY2024. Only two revenue lines are disclosed; AI revenue share is a proxy based on Pro Plus AI ACV / FY2024 revenue.
A6: Intuit | B6: INTU | C6: FY2025 | D6: 18.831 | E6: 4.923 | G6: Global Business Solutions | H6: 11.077 | I6: Consumer | J6: 4.87 | K6: Credit Karma | L6: 2.263 | M6: GenOS; Intuit Assist; QuickBooks AI agents; TurboTax AI | N6: Higher ARPR / assist upsell; platform expansion; agentic automation | O6: GenOS supports done-for-you agentic AI for ~100M customers; AI agents introduced across the business platform | P6: https://investors.intuit.com/sec-filings/all-sec-filings/content/0000896878-25-000035/0000896878-25-000035.pdf | Q6: https://investors.intuit.com/news-events/press-releases/detail/1254/intuit-supercharges-genos-for-delivery-of-done-for-you-agentic-ai-experiences-to-~100-million-consumers-businesses | R6: FY2026 combines Consumer, Credit Karma and ProTax into one Consumer segment; FY2025 segment view retained. No directly disclosed FY2025 AI revenue share.
A7: Palantir | B7: PLTR | C7: FY2025 | D7: 4.475446 | E7: 1.414015 | G7: Government | H7: 2.402287 | I7: Commercial | J7: 2.073159 | M7: AIP; Foundry; Gotham | N7: Platform subscriptions; deployment expansion; bootcamp-led conversion and expansion | O7: AIP bootcamps deliver workflows on actual customer data in days; commercial remaining deal value $6.8B (+117% YoY) | P7: https://investors.palantir.com/files/2025%20FY%20PLTR%2010-K.pdf | Q7: https://investors.palantir.com/news-details/2026/Palantir-Reports-Q4-2025-U-S--Comm-Revenue-Growth-of-137-YY-and-Revenue-Growth-of-70-YY-Issues-FY-2026-Revenue-Guidance-of-61-YY-and-U-S--Comm-Revenue-Guidance-of-115-YY-Crushing-Consensus-Expectations/ | R7: Palantir discloses revenue by Government and Commercial customers. No directly disclosed AI-only revenue share because AI is embedded across offerings.

Sheet Assumptions
A1: Company | B1: Scenario | C1: Baseline_Growth_2026_% | D1: Baseline_Growth_2027_% | E1: AI_Exposed_Revenue_% | F1: AI_Adoption_2026_% | G1: AI_Adoption_2027_% | H1: Monetization_Yield_2026_% | I1: Monetization_Yield_2027_% | J1: Cannibalization_2026_% | K1: Cannibalization_2027_% | L1: Assumption_Notes
A2: Microsoft | B2: Low | C2: 0.09 | D2: 0.08 | E2: 0.35 | F2: 0.07 | G2: 0.12 | H2: 0.04 | I2: 0.05 | J2: 0.002 | K2: 0.003 | L2: Low case: Azure AI demand remains strong but Copilot attach stays gradual; limited premium realization and some bundling friction.
A3: Microsoft | B3: Base | C3: 0.11 | D3: 0.1 | E3: 0.45 | F3: 0.12 | G3: 0.18 | H3: 0.06 | I3: 0.07 | J3: 0.004 | K3: 0.005 | L3: Base case: Azure AI consumption and Copilot penetration expand across M365, GitHub and Dynamics with manageable bundling pressure.
A4: Microsoft | B4: High | C4: 0.13 | D4: 0.12 | E4: 0.55 | F4: 0.18 | G4: 0.26 | H4: 0.08 | I4: 0.1 | J4: 0.006 | K4: 0.008 | L4: High case: broader Copilot adoption, stronger premium mix and faster Azure AI usage growth across the enterprise base.
A5: Salesforce | B5: Low | C5: 0.07 | D5: 0.06 | E5: 0.45 | F5: 0.1 | G5: 0.15 | H5: 0.05 | I5: 0.06 | J5: 0.003 | K5: 0.004 | L5: Low case: Agentforce pilots convert slowly and AI remains concentrated in larger accounts with modest wallet-share gains.
A6: Salesforce | B6: Base | C6: 0.09 | D6: 0.08 | E6: 0.6 | F6: 0.18 | G6: 0.26 | H6: 0.07 | I6: 0.085 | J6: 0.005 | K6: 0.006 | L6: Base case: Agentforce, Data Cloud and Einstein drive attach within Customer 360; paid deal conversion supports upsell and expansion.
A7: Salesforce | B7: High | C7: 0.11 | D7: 0.1 | E7: 0.7 | F7: 0.28 | G7: 0.36 | H7: 0.09 | I7: 0.11 | J7: 0.007 | K7: 0.009 | L7: High case: digital labor adoption accelerates, Data Cloud becomes a broader prerequisite and AI upsell spreads across the installed base.
A8: Adobe | B8: Low | C8: 0.08 | D8: 0.07 | E8: 0.4 | F8: 0.09 | G8: 0.14 | H8: 0.045 | I8: 0.055 | J8: 0.004 | K8: 0.005 | L8: Low case: Firefly and Acrobat AI usage rises, but monetization is partly offset by credits included in existing plans.
A9: Adobe | B9: Base | C9: 0.1 | D9: 0.09 | E9: 0.55 | F9: 0.16 | G9: 0.24 | H9: 0.065 | I9: 0.075 | J9: 0.006 | K9: 0.007 | L9: Base case: Firefly subscriptions, credit overages and Acrobat AI Assistant gradually lift ARPU while some features become table stakes.
A10: Adobe | B10: High | C10: 0.12 | D10: 0.11 | E10: 0.65 | F10: 0.24 | G10: 0.34 | H10: 0.085 | I10: 0.095 | J10: 0.008 | K10: 0.01 | L10: High case: stronger creator and enterprise uptake of Firefly, Express and GenStudio drives meaningful premium-plan and usage-based mix shift.
A11: ServiceNow | B11: Low | C11: 0.18 | D11: 0.16 | E11: 0.45 | F11: 0.1 | G11: 0.15 | H11: 0.05 | I11: 0.06 | J11: 0.002 | K11: 0.003 | L11: Low case: Now Assist and AI agents expand mainly through selected workflows; enterprise rollout stays measured despite strong core demand.
A12: ServiceNow | B12: Base | C12: 0.21 | D12: 0.19 | E12: 0.6 | F12: 0.18 | G12: 0.26 | H12: 0.075 | I12: 0.085 | J12: 0.003 | K12: 0.004 | L12: Base case: Pro Plus / Enterprise Plus and agentic AI broaden within existing workflow customers, lifting subscription expansion.
A13: ServiceNow | B13: High | C13: 0.24 | D13: 0.22 | E13: 0.7 | F13: 0.28 | G13: 0.36 | H13: 0.095 | I13: 0.11 | J13: 0.005 | K13: 0.006 | L13: High case: AI agents become a larger platform standard, adoption spreads beyond service workflows and premium-tier migration accelerates.
... A19: Palantir | B19: High | C19: 0.45 | D19: 0.35 | E19: 0.85 | F19: 0.3 | G19: 0.4 | H19: 0.11 | I19: 0.12 | J19: 0.003 | K19: 0.004 | L19: High case: AIP becomes a major enterprise deployment standard, sustaining very high conversion and expansion from new and existing accounts.

Sheet Scenario_Model
A1: Selected Scenario | B1: Base | D1: Tip: update Assumptions sheet, then switch scenario here.
A4: Company | B4: Revenue_2025 | C4: Base_Growth_2026_% | D4: AI_Exposed_% | E4: Revenue_2026_Baseline | F4: AI_Base_2026 | G4: Adoption_2026_% | H4: Monetization_2026_% | I4: AI_Uplift_2026 | J4: Cannibalization_2026_% | K4: Cannibalization_2026 | L4: Net_Revenue_2026 | M4: Base_Growth_2027_% | N4: Revenue_2027_Baseline | O4: AI_Base_2027 | P4: Adoption_2027_% | Q4: Monetization_2027_% | R4: AI_Uplift_2027 | S4: Cannibalization_2027_% | T4: Cannibalization_2027 | U4: Net_Revenue_2027
A5: Microsoft | B5: =SUMIFS(Raw_Data!$D:$D,Raw_Data!$A:$A,$A5) -> 281.724 | C5: =SUMIFS(Assumptions!$C:$C,Assumptions!$A:$A,$A5,Assumptions!$B:$B,$B$1) -> 0.11 | D5: =SUMIFS(Assumptions!$E:$E,Assumptions!$A:$A,$A5,Assumptions!$B:$B,$B$1) -> 0.45 | E5: =B5*(1+C5) -> 312.71364 | F5: =E5*D5 -> 140.72114 | G5: =SUMIFS(Assumptions!$F:$F,Assumptions!$A:$A,$A5,Assumptions!$B:$B,$B$1) -> 0.12 | H5: =SUMIFS(Assumptions!$H:$H,Assumptions!$A:$A,$A5,Assumptions!$B:$B,$B$1) -> 0.06 | I5: =F5*G5*H5 -> 1.0131922 | J5: =SUMIFS(Assumptions!$J:$J,Assumptions!$A:$A,$A5,Assumptions!$B:$B,$B$1) -> 0.004 | K5: =F5*J5 -> 0.56288455 | L5: =E5+I5-K5 -> 313.16395 | M5: =SUMIFS(Assumptions!$D:$D,Assumptions!$A:$A,$A5,Assumptions!$B:$B,$B$1) -> 0.1 | N5: =L5*(1+M5) -> 344.48034 | O5: =N5*D5 -> 155.01615 | P5: =SUMIFS(Assumptions!$G:$G,Assumptions!$A:$A,$A5,Assumptions!$B:$B,$B$1) -> 0.18 | Q5: =SUMIFS(Assumptions!$I:$I,Assumptions!$A:$A,$A5,Assumptions!$B:$B,$B$1) -> 0.07 | R5: =O5*P5*Q5 -> 1.9532035 | S5: =SUMIFS(Assumptions!$K:$K,Assumptions!$A:$A,$A5,Assumptions!$B:$B,$B$1) -> 0.005 | T5: =O5*S5 -> 0.77508077 | U5: =N5+R5-T5 -> 345.65847
A6: Salesforce | B6: =SUMIFS(Raw_Data!$D:$D,Raw_Data!$A:$A,$A6) -> 37.895 | C6: =SUMIFS(Assumptions!$C:$C,Assumptions!$A:$A,$A6,Assumptions!$B:$B,$B$1) -> 0.09 | D6: =SUMIFS(Assumptions!$E:$E,Assumptions!$A:$A,$A6,Assumptions!$B:$B,$B$1) -> 0.6 | E6: =B6*(1+C6) -> 41.30555 | F6: =E6*D6 -> 24.78333 | G6: =SUMIFS(Assumptions!$F:$F,Assumptions!$A:$A,$A6,Assumptions!$B:$B,$B$1) -> 0.18 | H6: =SUMIFS(Assumptions!$H:$H,Assumptions!$A:$A,$A6,Assumptions!$B:$B,$B$1) -> 0.07 | I6: =F6*G6*H6 -> 0.31226996 | J6: =SUMIFS(Assumptions!$J:$J,Assumptions!$A:$A,$A6,Assumptions!$B:$B,$B$1) -> 0.005 | K6: =F6*J6 -> 0.12391665 | L6: =E6+I6-K6 -> 41.493903 | M6: =SUMIFS(Assumptions!$D:$D,Assumptions!$A:$A,$A6,Assumptions!$B:$B,$B$1) -> 0.08 | N6: =L6*(1+M6) -> 44.813416 | O6: =N6*D6 -> 26.888049 | P6: =SUMIFS(Assumptions!$G:$G,Assumptions!$A:$A,$A6,Assumptions!$B:$B,$B$1) -> 0.26 | Q6: =SUMIFS(Assumptions!$I:$I,Assumptions!$A:$A,$A6,Assumptions!$B:$B,$B$1) -> 0.085 | R6: =O6*P6*Q6 -> 0.59422589 | S6: =SUMIFS(Assumptions!$K:$K,Assumptions!$A:$A,$A6,Assumptions!$B:$B,$B$1) -> 0.006 | T6: =O6*S6 -> 0.1613283 | U6: =N6+R6-T6 -> 45.246313
A7: Adobe | B7: =SUMIFS(Raw_Data!$D:$D,Raw_Data!$A:$A,$A7) -> 23.769 | C7: =SUMIFS(Assumptions!$C:$C,Assumptions!$A:$A,$A7,Assumptions!$B:$B,$B$1) -> 0.1 | D7: =SUMIFS(Assumptions!$E:$E,Assumptions!$A:$A,$A7,Assumptions!$B:$B,$B$1) -> 0.55 | E7: =B7*(1+C7) -> 26.1459 | F7: =E7*D7 -> 14.380245 | G7: =SUMIFS(Assumptions!$F:$F,Assumptions!$A:$A,$A7,Assumptions!$B:$B,$B$1) -> 0.16 | H7: =SUMIFS(Assumptions!$H:$H,Assumptions!$A:$A,$A7,Assumptions!$B:$B,$B$1) -> 0.065 | I7: =F7*G7*H7 -> 0.14955455 | J7: =SUMIFS(Assumptions!$J:$J,Assumptions!$A:$A,$A7,Assumptions!$B:$B,$B$1) -> 0.006 | K7: =F7*J7 -> 0.08628147 | L7: =E7+I7-K7 -> 26.209173 | M7: =SUMIFS(Assumptions!$D:$D,Assumptions!$A:$A,$A7,Assumptions!$B:$B,$B$1) -> 0.09 | N7: =L7*(1+M7) -> 28.567999 | O7: =N7*D7 -> 15.712399 | P7: =SUMIFS(Assumptions!$G:$G,Assumptions!$A:$A,$A7,Assumptions!$B:$B,$B$1) -> 0.24 | Q7: =SUMIFS(Assumptions!$I:$I,Assumptions!$A:$A,$A7,Assumptions!$B:$B,$B$1) -> 0.075 | R7: =O7*P7*Q7 -> 0.28282319 | S7: =SUMIFS(Assumptions!$K:$K,Assumptions!$A:$A,$A7,Assumptions!$B:$B,$B$1) -> 0.007 | T7: =O7*S7 -> 0.10998679 | U7: =N7+R7-T7 -> 28.740835
A8: ServiceNow | B8: =SUMIFS(Raw_Data!$D:$D,Raw_Data!$A:$A,$A8) -> 10.984 | C8: =SUMIFS(Assumptions!$C:$C,Assumptions!$A:$A,$A8,Assumptions!$B:$B,$B$1) -> 0.21 | D8: =SUMIFS(Assumptions!$E:$E,Assumptions!$A:$A,$A8,Assumptions!$B:$B,$B$1) -> 0.6 | E8: =B8*(1+C8) -> 13.29064 | F8: =E8*D8 -> 7.974384 | G8: =SUMIFS(Assumptions!$F:$F,Assumptions!$A:$A,$A8,Assumptions!$B:$B,$B$1) -> 0.18 | H8: =SUMIFS(Assumptions!$H:$H,Assumptions!$A:$A,$A8,Assumptions!$B:$B,$B$1) -> 0.075 | I8: =F8*G8*H8 -> 0.10765418 | J8: =SUMIFS(Assumptions!$J:$J,Assumptions!$A:$A,$A8,Assumptions!$B:$B,$B$1) -> 0.003 | K8: =F8*J8 -> 0.023923152 | L8: =E8+I8-K8 -> 13.374371 | M8: =SUMIFS(Assumptions!$D:$D,Assumptions!$A:$A,$A8,Assumptions!$B:$B,$B$1) -> 0.19 | N8: =L8*(1+M8) -> 15.915502 | O8: =N8*D8 -> 9.5493009 | P8: =SUMIFS(Assumptions!$G:$G,Assumptions!$A:$A,$A8,Assumptions!$B:$B,$B$1) -> 0.26 | Q8: =SUMIFS(Assumptions!$I:$I,Assumptions!$A:$A,$A8,Assumptions!$B:$B,$B$1) -> 0.085 | R8: =O8*P8*Q8 -> 0.21103955 | S8: =SUMIFS(Assumptions!$K:$K,Assumptions!$A:$A,$A8,Assumptions!$B:$B,$B$1) -> 0.004 | T8: =O8*S8 -> 0.038197204 | U8: =N8+R8-T8 -> 16.088344
A9: Intuit | B9: =SUMIFS(Raw_Data!$D:$D,Raw_Data!$A:$A,$A9) -> 18.831 | C9: =SUMIFS(Assumptions!$C:$C,Assumptions!$A:$A,$A9,Assumptions!$B:$B,$B$1) -> 0.12 | D9: =SUMIFS(Assumptions!$E:$E,Assumptions!$A:$A,$A9,Assumptions!$B:$B,$B$1) -> 0.5 | E9: =B9*(1+C9) -> 21.09072 | F9: =E9*D9 -> 10.54536 | G9: =SUMIFS(Assumptions!$F:$F,Assumptions!$A:$A,$A9,Assumptions!$B:$B,$B$1) -> 0.14 | H9: =SUMIFS(Assumptions!$H:$H,Assumptions!$A:$A,$A9,Assumptions!$B:$B,$B$1) -> 0.055 | I9: =F9*G9*H9 -> 0.081199272 | J9: =SUMIFS(Assumptions!$J:$J,Assumptions!$A:$A,$A9,Assumptions!$B:$B,$B$1) -> 0.003 | K9: =F9*J9 -> 0.03163608 | L9: =E9+I9-K9 -> 21.140283 | M9: =SUMIFS(Assumptions!$D:$D,Assumptions!$A:$A,$A9,Assumptions!$B:$B,$B$1) -> 0.11 | N9: =L9*(1+M9) -> 23.465714 | O9: =N9*D9 -> 11.732857 | P9: =SUMIFS(Assumptions!$G:$G,Assumptions!$A:$A,$A9,Assumptions!$B:$B,$B$1) -> 0.22 | Q9: =SUMIFS(Assumptions!$I:$I,Assumptions!$A:$A,$A9,Assumptions!$B:$B,$B$1) -> 0.065 | R9: =O9*P9*Q9 -> 0.16777986 | S9: =SUMIFS(Assumptions!$K:$K,Assumptions!$A:$A,$A9,Assumptions!$B:$B,$B$1) -> 0.004 | T9: =O9*S9 -> 0.046931429 | U9: =N9+R9-T9 -> 23.586563
A10: Palantir | B10: =SUMIFS(Raw_Data!$D:$D,Raw_Data!$A:$A,$A10) -> 4.475446 | C10: =SUMIFS(Assumptions!$C:$C,Assumptions!$A:$A,$A10,Assumptions!$B:$B,$B$1) -> 0.35 | D10: =SUMIFS(Assumptions!$E:$E,Assumptions!$A:$A,$A10,Assumptions!$B:$B,$B$1) -> 0.75 | E10: =B10*(1+C10) -> 6.0418521 | F10: =E10*D10 -> 4.5313891 | G10: =SUMIFS(Assumptions!$F:$F,Assumptions!$A:$A,$A10,Assumptions!$B:$B,$B$1) -> 0.2 | H10: =SUMIFS(Assumptions!$H:$H,Assumptions!$A:$A,$A10,Assumptions!$B:$B,$B$1) -> 0.09 | I10: =F10*G10*H10 -> 0.081565003 | J10: =SUMIFS(Assumptions!$J:$J,Assumptions!$A:$A,$A10,Assumptions!$B:$B,$B$1) -> 0.002 | K10: =F10*J10 -> 0.0090627782 | L10: =E10+I10-K10 -> 6.1143543 | M10: =SUMIFS(Assumptions!$D:$D,Assumptions!$A:$A,$A10,Assumptions!$B:$B,$B$1) -> 0.28 | N10: =L10*(1+M10) -> 7.8263735 | O10: =N10*D10 -> 5.8697802 | P10: =SUMIFS(Assumptions!$G:$G,Assumptions!$A:$A,$A10,Assumptions!$B:$B,$B$1) -> 0.3 | Q10: =SUMIFS(Assumptions!$I:$I,Assumptions!$A:$A,$A10,Assumptions!$B:$B,$B$1) -> 0.1 | R10: =O10*P10*Q10 -> 0.1760934 | S10: =SUMIFS(Assumptions!$K:$K,Assumptions!$A:$A,$A10,Assumptions!$B:$B,$B$1) -> 0.0025 | T10: =O10*S10 -> 0.01467445 | U10: =N10+R10-T10 -> 7.9877925
A11: Total | B11: =SUM(B5:B10) -> 377.67845 | E11: =SUM(E5:E10) -> 420.5883 | F11: =SUM(F5:F10) -> 202.93585 | I11: =SUM(I5:I10) -> 1.7454352 | K11: =SUM(K5:K10) -> 0.83770468 | L11: =SUM(L5:L10) -> 421.49603 | N11: =SUM(N5:N10) -> 465.06935 | O11: =SUM(O5:O10) -> 224.76854 | R11: =SUM(R5:R10) -> 3.3851654 | T11: =SUM(T5:T10) -> 1.1461989 | U11: =SUM(U5:U10) -> 467.30831
A13: Review point: | B13: If cannibalization exceeds AI uplift or net revenue looks flat, revise the underlying scenario assumptions.

Sheet Revenue_Mix
A1: Revenue Mix View | J1: Revenue Mix Insights (Base Scenario)
A2: Selected scenario follows Scenario_Model!B1 | J2: 2027 AI share is modeled as the 2025 AI proxy plus incremental AI uplift share from 2026–2027.
A4: Company | B4: AI_Share_2025_% | C4: Legacy_Share_2025_% | D4: AI_Share_2026_% | E4: Legacy_Share_2026_% | F4: AI_Share_2027_% | G4: Legacy_Share_2027_% | H4: Shift_in_AI_Share_2027_vs_2025_% | J4: Company | K4: AI Share 2025 | L4: AI Share 2027 | M4: Shift (pts) | N4: Interpretation
A5: Microsoft | B5: =IFERROR(SUMIFS(Raw_Data!$F:$F,Raw_Data!$A:$A,$A5),0) -> 0.046144453 | C5: =1-B5 -> 0.95385555 | D5: =MIN(1,B5+IFERROR(Scenario_Model!I5/Scenario_Model!L5,0)) -> 0.049379795 | E5: =1-D5 -> 0.95062021 | F5: =MIN(1,B5+IFERROR(Scenario_Model!I5/Scenario_Model!L5,0)+IFERROR(Scenario_Model!R5/Scenario_Model!U5,0)) -> 0.055030469 | G5: =1-F5 -> 0.94496953 | H5: =F5-B5 -> 0.0088860158 | J5: Microsoft | K5: =B5 -> 0.046144453 | L5: =F5 -> 0.055030469 | M5: =H5 -> 0.0088860158 | N5: Largest absolute AI uplift, but mix shift is modest because the revenue base is very large.
A6: Salesforce | B6: =IFERROR(SUMIFS(Raw_Data!$F:$F,Raw_Data!$A:$A,$A6),0) -> 0.023749835 | C6: =1-B6 -> 0.97625016 | D6: =MIN(1,B6+IFERROR(Scenario_Model!I6/Scenario_Model!L6,0)) -> 0.031275518 | E6: =1-D6 -> 0.96872448 | F6: =MIN(1,B6+IFERROR(Scenario_Model!I6/Scenario_Model!L6,0)+IFERROR(Scenario_Model!R6/Scenario_Model!U6,0)) -> 0.044408652 | G6: =1-F6 -> 0.95559135 | H6: =F6-B6 -> 0.020658817 | J6: Salesforce | K6: =B6 -> 0.023749835 | L6: =F6 -> 0.044408652 | M6: =H6 -> 0.020658817 | N6: Clear agentic AI monetization story; AI share expands through Agentforce and Data Cloud upsell.
A7: Adobe | B7: =IFERROR(SUMIFS(Raw_Data!$F:$F,Raw_Data!$A:$A,$A7),0) -> 0 | C7: =1-B7 -> 1 | D7: =MIN(1,B7+IFERROR(Scenario_Model!I7/Scenario_Model!L7,0)) -> 0.005706191 | E7: =1-D7 -> 0.99429381 | F7: =MIN(1,B7+IFERROR(Scenario_Model!I7/Scenario_Model!L7,0)+IFERROR(Scenario_Model!R7/Scenario_Model!U7,0)) -> 0.015546656 | G7: =1-F7 -> 0.98445334 | H7: =F7-B7 -> 0.015546656 | J7: Adobe | K7: =B7 -> 0 | L7: =F7 -> 0.015546656 | M7: =H7 -> 0.015546656 | N7: Mix shifts gradually through Firefly plans, credits, and AI-enhanced premium subscriptions.
A8: ServiceNow | B8: =IFERROR(SUMIFS(Raw_Data!$F:$F,Raw_Data!$A:$A,$A8),0) -> 0.018208303 | C8: =1-B8 -> 0.9817917 | D8: =MIN(1,B8+IFERROR(Scenario_Model!I8/Scenario_Model!L8,0)) -> 0.026257592 | E8: =1-D8 -> 0.97374241 | F8: =MIN(1,B8+IFERROR(Scenario_Model!I8/Scenario_Model!L8,0)+IFERROR(Scenario_Model!R8/Scenario_Model!U8,0)) -> 0.039375136 | G8: =1-F8 -> 0.96062486 | H8: =F8-B8 -> 0.021166833 | J8: ServiceNow | K8: =B8 -> 0.018208303 | L8: =F8 -> 0.039375136 | M8: =H8 -> 0.021166833 | N8: Strong relative mix improvement driven by Now Assist / Pro Plus AI expansion inside existing workflows.
A9: Intuit | B9: =IFERROR(SUMIFS(Raw_Data!$F:$F,Raw_Data!$A:$A,$A9),0) -> 0 | C9: =1-B9 -> 1 | D9: =MIN(1,B9+IFERROR(Scenario_Model!I9/Scenario_Model!L9,0)) -> 0.0038409737 | E9: =1-D9 -> 0.99615903 | F9: =MIN(1,B9+IFERROR(Scenario_Model!I9/Scenario_Model!L9,0)+IFERROR(Scenario_Model!R9/Scenario_Model!U9,0)) -> 0.01095434 | G9: =1-F9 -> 0.98904566 | H9: =F9-B9 -> 0.01095434 | J9: Intuit | K9: =B9 -> 0 | L9: =F9 -> 0.01095434 | M9: =H9 -> 0.01095434 | N9: Moderate mix shift as AI becomes embedded across SMB finance, tax, and assist workflows.
A10: Palantir | B10: =IFERROR(SUMIFS(Raw_Data!$F:$F,Raw_Data!$A:$A,$A10),0) -> 0 | C10: =1-B10 -> 1 | D10: =MIN(1,B10+IFERROR(Scenario_Model!I10/Scenario_Model!L10,0)) -> 0.013339921 | E10: =1-D10 -> 0.98666008 | F10: =MIN(1,B10+IFERROR(Scenario_Model!I10/Scenario_Model!L10,0)+IFERROR(Scenario_Model!R10/Scenario_Model!U10,0)) -> 0.035385236 | G10: =1-F10 -> 0.96461476 | H10: =F10-B10 -> 0.035385236 | J10: Palantir | K10: =B10 -> 0 | L10: =F10 -> 0.035385236 | M10: =H10 -> 0.035385236 | N10: Biggest mix shift in the model, helped by high AI exposure and a smaller starting revenue base.
J12: Top Takeaways
J13: • Microsoft delivers the largest absolute 2027 AI uplift, while Palantir shows the biggest modeled mix shift.
J14: • Salesforce and ServiceNow show the strongest enterprise-software mix expansion from agentic/workflow AI upsell.
J15: • Adobe and Intuit show steadier mix change because monetization is tied more to plan upgrades and workflow embedment than pure consumption.

Sheet Charts
A1: Dashboard — AI Revenue Impact Model
A2: Charts are linked to Scenario_Model and Revenue_Mix. Scenario comparison uses helper formulas for Low/Base/High 2027 outcomes.
G3: Low | H3: Base | I3: High
A4: Company | B4: Revenue_2025 | C4: Net_Revenue_2027 | D4: AI_Share_2027_% | F4: Company | G4: Low_2027 | H4: Base_2027 | I4: High_2027 | K4: Company | L4: AI_Uplift_2027 | M4: Cannibalization_2027 | O4: Company | P4: AI_Share_2025_% | Q4: AI_Share_2027_%
A5: Microsoft | B5: =Scenario_Model!B5 -> 281.724 | C5: =Scenario_Model!U5 -> 345.65847 | D5: =Revenue_Mix!F5 -> 0.055030469 | F5: Microsoft | G5: =((SUMIFS(Raw_Data!$D:$D,Raw_Data!$A:$A,$F5)*(1+SUMIFS(Assumptions!$C:$C,Assumptions!$A:$A,$F5,Assumptions!$B:$B,"Low"))+(SUMIFS(Raw_Data!$D:$D,Raw_Data!$A:$A,$F5)*(1+SUMIFS(Assumptions!$C:$C,Assumptions!$A:$A,$F5,Assumptions!$B:$B,"Low"))*SUMIFS(Assumptions!$E:$E,Assumptions!$A:$A,$F5,Assumptions!$B:$B,"Low")*SUMIFS(Assumptions!$F:$F,Assumptions!$A:$A,$F5,Assumptions!$B:$B,"Low")*SUMIFS(Assumptions!$H:$H,Assumptions!$A:$A,$F5,Assumptions!$B:$B,"Low"))-(SUMIFS(Raw_Data!$D:$D,Raw_Data!$A:$A,$F5)*(1+SUMIFS(Assumptions!$C:$C,Assumptions!$A:$A,$F5,Assumptions!$B:$B,"Low"))*SUMIFS(Assumptions!$E:$E,Assumptions!$A:$A,$F5,Assumptions!$B:$B,"Low")*SUMIFS(Assumptions!$J:$J,Assumptions!$A:$A,$F5,Assumptions!$B:$B,"Low")))*(1+SUMIFS(Assumptions!$D:$D,Assumptions!$A:$A,$F5,Assumptions!$B:$B,"Low"))+(((SUMIFS(Raw_Data!$D:$D,Raw_Data!$A:$A,$F5)*(1+SUMIFS(Assumptions!$C:$C,Assumptions!$A:$A,$F5,Assumptions!$B:$B,"Low"))+(SUMIFS(Raw_Data!$D:$D,Raw_Data!$A:$A,$F5)*(1+SUMIFS(Assumptions!$C:$C,Assumptions!$A:$A,$F5,Assumptions!$B:$B,"Low"))*SUMIFS(Assumptions!$E:$E,Assumptions!$A:$A,$F5,Assumptions!$B:$B,"Low")*SUMIFS(Assumptions!$F:$F,Assumptions!$A:$A,$F5,Assumptions!$B:$B,"Low")*SUMIFS(Assumptions!$H:$H,Assumptions!$A:$A,$F5,Assumptions!$B:$B,"Low"))-(SUMIFS(Raw_Data!$D:$D,Raw_Data!$A:$A,$F5)*(1+SUMIFS(Assumptions!$C:$C,Assumptions!$A:$A,$F5,Assumptions!$B:$B,"Low"))*SUMIFS(Assumptions!$E:$E,Assumptions!$A:$A,$F5,Assumptions!$B:$B,"Low")*SUMIFS(Assumptions!$J:$J,Assumptions!$A:$A,$F5,Assumptions!$B:$B,"Low")))*(1+SUMIFS(Assumptions!$D:$D,Assumptions!$A:$A,$F5,Assumptions!$B:$B,"Low"))*SUMIFS(Assumptions!$E:$E,Assumptions!$A:$A,$F5,Assumptions!$B:$B,"Low")*SUMIFS(Assumptions!$G:$G,Assumptions!$A:$A,$F5,Assumptions!$B:$B,"Low")*SUMIFS(Assumptions!$I:$I,Assumptions!$A:$A,$F5,Assumptions!$B:$B,"Low"))-(((SUMIFS(Raw_Data!$D:$D,Raw_Data!$A:$A,$F5)*(1+SUMIFS(Assumptions!$C:$C,Assumptions!$A:$A,$F5,Assumptions!$B:$B,"Low"))+(SUMIFS(Raw_Data!$D:$D,Raw_Data!$A:$A,$F5)*(1+SUMIFS(Assumptions!$C:$C,Assumptions!$A:$A,$F5,Assumptions!$B:$B,"Low"))*SUMIFS(Assumptions!$E:$E,Assumptions!$A:$A,$F5,Assumptions!$B:$B,"Low")*SUMIFS(Assumptions!$F:$F,Assumptions!$A:$A,$F5,Assumptions!$B:$B,"Low")*SUMIFS(Assumptions!$H:$H,Assumptions!$A:$A,$F5,Assumptions!$B:$B,"Low"))-(SUMIFS(Raw_Data!$D:$D,Raw_Data!$A:$A,$F5)*(1+SUMIFS(Assumptions!$C:$C,Assumptions!$A:$A,$F5,Assumptions!$B:$B,"Low"))*SUMIFS(Assumptions!$E:$E,Assumptions!$A:$A,$F5,Assumptions!$B:$B,"Low")*SUMIFS(Assumptions!$J:$J,Assumptions!$A:$A,$F5,Assumptions!$B:$B,"Low")))*(1+SUMIFS(Assumptions!$D:$D,Assumptions!$A:$A,$F5,Assumptions!$B:$B,"Low"))*SUMIFS(Assumptions!$E:$E,Assumptions!$A:$A,$F5,Assumptions!$B:$B,"Low")*SUMIFS(Assumptions!$K:$K,Assumptions!$A:$A,$F5,Assumptions!$B:$B,"Low"))))) -> 332.08668 | H5: =((SUMIFS(Raw_Data!$D:$D,Raw_Data!$A:$A,$F5)*(1+SUMIFS(Assumptions!$C:$C,Assumptions!$A:$A,$F5,Assumptions!$B:$B,"Base"))+(SUMIFS(Raw_Data!$D:$D,Raw_Data!$A:$A,$F5)*(1+SUMIFS(Assumptions!$C:$C,Assumptions!$A:$A,$F5,Assumptions!$B:$B,"Base"))*SUMIFS(Assumptions!$E:$E,Assumptions!$A:$A,$F5,Assumptions!$B:$B,"Base")*SUMIFS(Assumptions!$F:$F,Assumptions!$A:$A,$F5,Assumptions!$B:$B,"Base")*SUMIFS(Assumptions!$H:$H,Assumptions!$A:$A,$F5,Assumptions!$B:$B,"Base"))-(SUMIFS(Raw_Data!$D:$D,Raw_Data!$A:$A,$F5)*(1+SUMIFS(Assumptions!$C:$C,Assumptions!$A:$A,$F5,Assumptions!$B:$B,"Base"))*SUMIFS(Assumptions!$E:$E,Assumptions!$A:$A,$F5,Assumptions!$B:$B,"Base")*SUMIFS(Assumptions!$J:$J,Assumptions!$A:$A,$F5,Assumptions!$B:$B,"Base")))*(1+SUMIFS(Assumptions!$D:$D,Assumptions!$A:$A,$F5,Assumptions!$B:$B,"Base"))+(((SUMIFS(Raw_Data!$D:$D,Raw_Data!$A:$A,$F5)*(1+SUMIFS(Assumptions!$C:$C,Assumptions!$A:$A,$F5,Assumptions!$B:$B,"Base"))+(SUMIFS(Raw_Data!$D:$D,Raw_Data!$A:$A,$F5)*(1+SUMIFS(Assumptions!$C:$C,Assumptions!$A:$A,$F5,Assumptions!$B:$B,"Base"))*SUMIFS(Assumptions!$E:$E,Assumptions!$A:$A,$F5,Assumptions!$B:$B,"Base")*SUMIFS(Assumptions!$F:$F,Assumptions!$A:$A,$F5,Assumptions!$B:$B,"Base")*SUMIFS(Assumptions!$H:$H,Assumptions!$A:$A,$F5,Assumptions!$B:$B,"Base"))-(SUMIFS(Raw_Data!$D:$D,Raw_Data!$A:$A,$F5)*(1+SUMIFS(Assumptions!$C:$C,Assumptions!$A:$A,$F5,Assumptions!$B:$B,"Base"))*SUMIFS(Assumptions!$E:$E,Assumptions!$A:$A,$F5,Assumptions!$B:$B,"Base")*SUMIFS(Assumptions!$J:$J,Assumptions!$A:$A,$F5,Assumptions!$B:$B,"Base")))*(1+SUMIFS(Assumptions!$D:$D,Assumptions!$A:$A,$F5,Assumptions!$B:$B,"Base"))*SUMIFS(Assumptions!$E:$E,Assumptions!$A:$A,$F5,Assumptions!$B:$B,"Base")*SUMIFS(Assumptions!$G:$G,Assumptions!$A:$A,$F5,Assumptions!$B:$B,"Base")*SUMIFS(Assumptions!$I:$I,Assumptions!$A:$A,$F5,Assumptions!$B:$B,"Base"))-(((SUMIFS(Raw_Data!$D:$D,Raw_Data!$A:$A,$F5)*(1+SUMIFS(Assumptions!$C:$C,Assumptions!$A:$A,$F5,Assumptions!$B:$B,"Base"))+(SUMIFS(Raw_Data!$D:$D,Raw_Data!$A:$A,$F5)*(1+SUMIFS(Assumptions!$C:$C,Assumptions!$A:$A,$F5,Assumptions!$B:$B,"Base"))*SUMIFS(Assumptions!$E:$E,Assumptions!$A:$A,$F5,Assumptions!$B:$B,"Base")*SUMIFS(Assumptions!$F:$F,Assumptions!$A:$A,$F5,Assumptions!$B:$B,"Base")*SUMIFS(Assumptions!$H:$H,Assumptions!$A:$A,$F5,Assumptions!$B:$B,"Base"))-(SUMIFS(Raw_Data!$D:$D,Raw_Data!$A:$A,$F5)*(1+SUMIFS(Assumptions!$C:$C,Assumptions!$A:$A,$F5,Assumptions!$B:$B,"Base"))*SUMIFS(Assumptions!$E:$E,Assumptions!$A:$A,$F5,Assumptions!$B:$B,"Base")*SUMIFS(Assumptions!$J:$J,Assumptions!$A:$A,$F5,Assumptions!$B:$B,"Base")))*(1+SUMIFS(Assumptions!$D:$D,Assumptions!$A:$A,$F5,Assumptions!$B:$B,"Base"))*SUMIFS(Assumptions!$E:$E,Assumptions!$A:$A,$F5,Assumptions!$B:$B,"Base")*SUMIFS(Assumptions!$K:$K,Assumptions!$A:$A,$F5,Assumptions!$B:$B,"Base"))))) -> 345.65847 | I5: =((SUMIFS(Raw_Data!$D:$D,Raw_Data!$A:$A,$F5)*(1+SUMIFS(Assumptions!$C:$C,Assumptions!$A:$A,$F5,Assumptions!$B:$B,"High"))+(SUMIFS(Raw_Data!$D:$D,Raw_Data!$A:$A,$F5)*(1+SUMIFS(Assumptions!$C:$C,Assumptions!$A:$A,$F5,Assumptions!$B:$B,"High"))*SUMIFS(Assumptions!$E:$E,Assumptions!$A:$A,$F5,Assumptions!$B:$B,"High")*SUMIFS(Assumptions!$F:$F,Assumptions!$A:$A,$F5,Assumptions!$B:$B,"High")*SUMIFS(Assumptions!$H:$H,Assumptions!$A:$A,$F5,Assumptions!$B:$B,"High"))-(SUMIFS(Raw_Data!$D:$D,Raw_Data!$A:$A,$F5)*(1+SUMIFS(Assumptions!$C:$C,Assumptions!$A:$A,$F5,Assumptions!$B:$B,"High"))*SUMIFS(Assumptions!$E:$E,Assumptions!$A:$A,$F5,Assumptions!$B:$B,"High")*SUMIFS(Assumptions!$J:$J,Assumptions!$A:$A,$F5,Assumptions!$B:$B,"High")))*(1+SUMIFS(Assumptions!$D:$D,Assumptions!$A:$A,$F5,Assumptions!$B:$B,"High"))+(((SUMIFS(Raw_Data!$D:$D,Raw_Data!$A:$A,$F5)*(1+SUMIFS(Assumptions!$C:$C,Assumptions!$A:$A,$F5,Assumptions!$B:$B,"High"))+(SUMIFS(Raw_Data!$D:$D,Raw_Data!$A:$A,$F5)*(1+SUMIFS(Assumptions!$C:$C,Assumptions!$A:$A,$F5,Assumptions!$B:$B,"High"))*SUMIFS(Assumptions!$E:$E,Assumptions!$A:$A,$F5,Assumptions!$B:$B,"High")*SUMIFS(Assumptions!$F:$F,Assumptions!$A:$A,$F5,Assumptions!$B:$B,"High")*SUMIFS(Assumptions!$H:$H,Assumptions!$A:$A,$F5,Assumptions!$B:$B,"High"))-(SUMIFS(Raw_Data!$D:$D,Raw_Data!$A:$A,$F5)*(1+SUMIFS(Assumptions!$C:$C,Assumptions!$A:$A,$F5,Assumptions!$B:$B,"High"))*SUMIFS(Assumptions!$E:$E,Assumptions!$A:$A,$F5,Assumptions!$B:$B,"High")*SUMIFS(Assumptions!$J:$J,Assumptions!$A:$A,$F5,Assumptions!$B:$B,"High")))*(1+SUMIFS(Assumptions!$D:$D,Assumptions!$A:$A,$F5,Assumptions!$B:$B,"High"))*SUMIFS(Assumptions!$E:$E,Assumptions!$A:$A,$F5,Assumptions!$B:$B,"High")*SUMIFS(Assumptions!$G:$G,Assumptions!$A:$A,$F5,Assumptions!$B:$B,"High")*SUMIFS(Assumptions!$I:$I,Assumptions!$A:$A,$F5,Assumptions!$B:$B,"High"))-(((SUMIFS(Raw_Data!$D:$D,Raw_Data!$A:$A,$F5)*(1+SUMIFS(Assumptions!$C:$C,Assumptions!$A:$A,$F5,Assumptions!$B:$B,"High"))+(SUMIFS(Raw_Data!$D:$D,Raw_Data!$A:$A,$F5)*(1+SUMIFS(Assumptions!$C:$C,Assumptions!$A:$A,$F5,Assumptions!$B:$B,"High"))*SUMIFS(Assumptions!$E:$E,Assumptions!$A:$A,$F5,Assumptions!$B:$B,"High")*SUMIFS(Assumptions!$F:$F,Assumptions!$A:$A,$F5,Assumptions!$B:$B,"High")*SUMIFS(Assumptions!$H:$H,Assumptions!$A:$A,$F5,Assumptions!$B:$B,"High"))-(SUMIFS(Raw_Data!$D:$D,Raw_Data!$A:$A,$F5)*(1+SUMIFS(Assumptions!$C:$C,Assumptions!$A:$A,$F5,Assumptions!$B:$B,"High"))*SUMIFS(Assumptions!$E:$E,Assumptions!$A:$A,$F5,Assumptions!$B:$B,"High")*SUMIFS(Assumptions!$J:$J,Assumptions!$A:$A,$F5,Assumptions!$B:$B,"High")))*(1+SUMIFS(Assumptions!$D:$D,Assumptions!$A:$A,$F5,Assumptions!$B:$B,"High"))*SUMIFS(Assumptions!$E:$E,Assumptions!$A:$A,$F5,Assumptions!$B:$B,"High")*SUMIFS(Assumptions!$K:$K,Assumptions!$A:$A,$F5,Assumptions!$B:$B,"High"))))) -> 361.74331 | K5: Microsoft | L5: =Scenario_Model!R5 -> 1.9532035 | M5: =Scenario_Model!T5 -> 0.77508077 | O5: Microsoft | P5: =Revenue_Mix!B5 -> 0.046144453 | Q5: =Revenue_Mix!F5 -> 0.055030469
A6: Salesforce | B6: =Scenario_Model!B6 -> 37.895 | C6: =Scenario_Model!U6 -> 45.246313 | D6: =Revenue_Mix!F6 -> 0.044408652 | F6: Salesforce | G6: =((SUMIFS(Raw_Data!$D:$D,Raw_Data!$A:$A,$F6)*(1+SUMIFS(Assumptions!$C:$C,Assumptions!$A:$A,$F6,Assumptions!$B:$B,"Low"))+(SUMIFS(Raw_Data!$D:$D,Raw_Data!$A:$A,$F6)*(1+SUMIFS(Assumptions!$C:$C,Assumptions!$A:$A,$F6,Assumptions!$B:$B,"Low"))*SUMIFS(Assumptions!$E:$E,Assumptions!$A:$A,$F6,Assumptions!$B:$B,"Low")*SUMIFS(Assumptions!$F:$F,Assumptions!$A:$A,$F6,Assumptions!$B:$B,"Low")*SUMIFS(Assumptions!$H:$H,Assumptions!$A:$A,$F6,Assumptions!$B:$B,"Low"))-(SUMIFS(Raw_Data!$D:$D,Raw_Data!$A:$A,$F6)*(1+SUMIFS(Assumptions!$C:$C,Assumptions!$A:$A,$F6,Assumptions!$B:$B,"Low"))*SUMIFS(Assumptions!$E:$E,Assumptions!$A:$A,$F6,Assumptions!$B:$B,"Low")*SUMIFS(Assumptions!$J:$J,Assumptions!$A:$A,$F6,Assumptions!$B:$B,"Low")))*(1+SUMIFS(Assumptions!$D:$D,Assumptions!$A:$A,$F6,Assumptions!$B:$B,"Low"))+(((SUMIFS(Raw_Data!$D:$D,Raw_Data!$A:$A,$F6)*(1+SUMIFS(Assumptions!$C:$C,Assumptions!$A:$A,$F6,Assumptions!$B:$B,"Low"))+(SUMIFS(Raw_Data!$D:$D,Raw_Data!$A:$A,$F6)*(1+SUMIFS(Assumptions!$C:$C,Assumptions!$A:$A,$F6,Assumptions!$B:$B,"Low"))*SUMIFS(Assumptions!$E:$E,Assumptions!$A:$A,$F6,Assumptions!$B:$B,"Low")*SUMIFS(Assumptions!$F:$F,Assumptions!$A:$A,$F6,Assumptions!$B:$B,"Low")*SUMIFS(Assumptions!$H:$H,Assumptions!$A:$A,$F6,Assumptions!$B:$B,"Low"))-(SUMIFS(Raw_Data!$D:$D,Raw_Data!$A:$A,$F6)*(1+SUMIFS(Assumptions!$C:$C,Assumptions!$A:$A,$F6,Assumptions!$B:$B,"Low"))*SUMIFS(Assumptions!$E:$E,Assumptions!$A:$A,$F6,Assumptions!$B:$B,"Low")*SUMIFS(Assumptions!$J:$J,Assumptions!$A:$A,$F6,Assumptions!$B:$B,"Low")))*(1+SUMIFS(Assumptions!$D:$D,Assumptions!$A:$A,$F6,Assumptions!$B:$B,"Low"))*SUMIFS(Assumptions!$E:$E,Assumptions!$A:$A,$F6,Assumptions!$B:$B,"Low")*SUMIFS(Assumptions!$G:$G,Assumptions!$A:$A,$F6,Assumptions!$B:$B,"Low")*SUMIFS(Assumptions!$I:$I,Assumptions!$A:$A,$F6,Assumptions!$B:$B,"Low"))-(((SUMIFS(Raw_Data!$D:$D,Raw_Data!$A:$A,$F6)*(1+SUMIFS(Assumptions!$C:$C,Assumptions!$A:$A,$F6,Assumptions!$B:$B,"Low"))+(SUMIFS(Raw_Data!$D:$D,Raw_Data!$A:$A,$F6)*(1+SUMIFS(Assumptions!$C:$C,Assumptions!$A:$A,$F6,Assumptions!$B:$B,"Low"))*SUMIFS(Assumptions!$E:$E,Assumptions!$A:$A,$F6,Assumptions!$B:$B,"Low")*SUMIFS(Assumptions!$F:$F,Assumptions!$A:$A,$F6,Assumptions!$B:$B,"Low")*SUMIFS(Assumptions!$H:$H,Assumptions!$A:$A,$F6,Assumptions!$B:$B,"Low"))-(SUMIFS(Raw_Data!$D:$D,Raw_Data!$A:$A,$F6)*(1+SUMIFS(Assumptions!$C:$C,Assumptions!$A:$A,$F6,Assumptions!$B:$B,"Low"))*SUMIFS(Assumptions!$E:$E,Assumptions!$A:$A,$F6,Assumptions!$B:$B,"Low")*SUMIFS(Assumptions!$J:$J,Assumptions!$A:$A,$F6,Assumptions!$B:$B,"Low")))*(1+SUMIFS(Assumptions!$D:$D,Assumptions!$A:$A,$F6,Assumptions!$B:$B,"Low"))*SUMIFS(Assumptions!$E:$E,Assumptions!$A:$A,$F6,Assumptions!$B:$B,"Low")*SUMIFS(Assumptions!$K:$K,Assumptions!$A:$A,$F6,Assumptions!$B:$B,"Low"))))) -> 43.115985 | H6: =((SUMIFS(Raw_Data!$D:$D,Raw_Data!$A:$A,$F6)*(1+SUMIFS(Assumptions!$C:$C,Assumptions!$A:$A,$F6,Assumptions!$B:$B,"Base"))+(SUMIFS(Raw_Data!$D:$D,Raw_Data!$A:$A,$F6)*(1+SUMIFS(Assumptions!$C:$C,Assumptions!$A:$A,$F6,Assumptions!$B:$B,"Base"))*SUMIFS(Assumptions!$E:$E,Assumptions!$A:$A,$F6,Assumptions!$B:$B,"Base")*SUMIFS(Assumptions!$F:$F,Assumptions!$A:$A,$F6,Assumptions!$B:$B,"Base")*SUMIFS(Assumptions!$H:$H,Assumptions!$A:$A,$F6,Assumptions!$B:$B,"Base"))-(SUMIFS(Raw_Data!$D:$D,Raw_Data!$A:$A,$F6)*(1+SUMIFS(Assumptions!$C:$C,Assumptions!$A:$A,$F6,Assumptions!$B:$B,"Base"))*SUMIFS(Assumptions!$E:$E,Assumptions!$A:$A,$F6,Assumptions!$B:$B,"Base")*SUMIFS(Assumptions!$J:$J,Assumptions!$A:$A,$F6,Assumptions!$B:$B,"Base")))*(1+SUMIFS(Assumptions!$D:$D,Assumptions!$A:$A,$F6,Assumptions!$B:$B,"Base"))+(((SUMIFS(Raw_Data!$D:$D,Raw_Data!$A:$A,$F6)*(1+SUMIFS(Assumptions!$C:$C,Assumptions!$A:$A,$F6,Assumptions!$B:$B,"Base"))+(SUMIFS(Raw_Data!$D:$D,Raw_Data!$A:$A,$F6)*(1+SUMIFS(Assumptions!$C:$C,Assumptions!$A:$A,$F6,Assumptions!$B:$B,"Base"))*SUMIFS(Assumptions!$E:$E,Assumptions!$A:$A,$F6,Assumptions!$B:$B,"Base")*SUMIFS(Assumptions!$F:$F,Assumptions!$A:$A,$F6,Assumptions!$B:$B,"Base")*SUMIFS(Assumptions!$H:$H,Assumptions!$A:$A,$F6,Assumptions!$B:$B,"Base"))-(SUMIFS(Raw_Data!$D:$D,Raw_Data!$A:$A,$F6)*(1+SUMIFS(Assumptions!$C:$C,Assumptions!$A:$A,$F6,Assumptions!$B:$B,"Base"))*SUMIFS(Assumptions!$E:$E,Assumptions!$A:$A,$F6,Assumptions!$B:$B,"Base")*SUMIFS(Assumptions!$J:$J,Assumptions!$A:$A,$F6,Assumptions!$B:$B,"Base")))*(1+SUMIFS(Assumptions!$D:$D,Assumptions!$A:$A,$F6,Assumptions!$B:$B,"Base"))*SUMIFS(Assumptions!$E:$E,Assumptions!$A:$A,$F6,Assumptions!$B:$B,"Base")*SUMIFS(Assumptions!$G:$G,Assumptions!$A:$A,$F6,Assumptions!$B:$B,"Base")*SUMIFS(Assumptions!$I:$I,Assumptions!$A:$A,$F6,Assumptions!$B:$B,"Base"))-(((SUMIFS(Raw_Data!$D:$D,Raw_Data!$A:$A,$F6)*(1+SUMIFS(Assumptions!$C:$C,Assumptions!$A:$A,$F6,Assumptions!$B:$B,"Base"))+(SUMIFS(Raw_Data!$D:$D,Raw_Data!$A:$A,$F6)*(1+SUMIFS(Assumptions!$C:$C,Assumptions!$A:$A,$F6,Assumptions!$B:$B,"Base"))*SUMIFS(Assumptions!$E:$E,Assumptions!$A:$A,$F6,Assumptions!$B:$B,"Base")*SUMIFS(Assumptions!$F:$F,Assumptions!$A:$A,$F6,Assumptions!$B:$B,"Base")*SUMIFS(Assumptions!$H:$H,Assumptions!$A:$A,$F6,Assumptions!$B:$B,"Base"))-(SUMIFS(Raw_Data!$D:$D,Raw_Data!$A:$A,$F6)*(1+SUMIFS(Assumptions!$C:$C,Assumptions!$A:$A,$F6,Assumptions!$B:$B,"Base"))*SUMIFS(Assumptions!$E:$E,Assumptions!$A:$A,$F6,Assumptions!$B:$B,"Base")*SUMIFS(Assumptions!$J:$J,Assumptions!$A:$A,$F6,Assumptions!$B:$B,"Base")))*(1+SUMIFS(Assumptions!$D:$D,Assumptions!$A:$A,$F6,Assumptions!$B:$B,"Base"))*SUMIFS(Assumptions!$E:$E,Assumptions!$A:$A,$F6,Assumptions!$B:$B,"Base")*SUMIFS(Assumptions!$K:$K,Assumptions!$A:$A,$F6,Assumptions!$B:$B,"Base"))))) -> 45.246313 | I6: =((SUMIFS(Raw_Data!$D:$D,Raw_Data!$A:$A,$F6)*(1+SUMIFS(Assumptions!$C:$C,Assumptions!$A:$A,$F6,Assumptions!$B:$B,"High"))+(SUMIFS(Raw_Data!$D:$D,Raw_Data!$A:$A,$F6)*(1+SUMIFS(Assumptions!$C:$C,Assumptions!$A:$A,$F6,Assumptions!$B:$B,"High"))*SUMIFS(Assumptions!$E:$E,Assumptions!$A:$A,$F6,Assumptions!$B:$B,"High")*SUMIFS(Assumptions!$F:$F,Assumptions!$A:$A,$F6,Assumptions!$B:$B,"High")*SUMIFS(Assumptions!$H:$H,Assumptions!$A:$A,$F6,Assumptions!$B:$B,"High"))-(SUMIFS(Raw_Data!$D:$D,Raw_Data!$A:$A,$F6)*(1+SUMIFS(Assumptions!$C:$C,Assumptions!$A:$A,$F6,Assumptions!$B:$B,"High"))*SUMIFS(Assumptions!$E:$E,Assumptions!$A:$A,$F6,Assumptions!$B:$B,"High")*SUMIFS(Assumptions!$J:$J,Assumptions!$A:$A,$F6,Assumptions!$B:$B,"High")))*(1+SUMIFS(Assumptions!$D:$D,Assumptions!$A:$A,$F6,Assumptions!$B:$B,"High"))+(((SUMIFS(Raw_Data!$D:$D,Raw_Data!$A:$A,$F6)*(1+SUMIFS(Assumptions!$C:$C,Assumptions!$A:$A,$F6,Assumptions!$B:$B,"High"))+(SUMIFS(Raw_Data!$D:$D,Raw_Data!$A:$A,$F6)*(1+SUMIFS(Assumptions!$C:$C,Assumptions!$A:$A,$F6,Assumptions!$B:$B,"High"))*SUMIFS(Assumptions!$E:$E,Assumptions!$A:$A,$F6,Assumptions!$B:$B,"High")*SUMIFS(Assumptions!$F:$F,Assumptions!$A:$A,$F6,Assumptions!$B:$B,"High")*SUMIFS(Assumptions!$H:$H,Assumptions!$A:$A,$F6,Assumptions!$B:$B,"High"))-(SUMIFS(Raw_Data!$D:$D,Raw_Data!$A:$A,$F6)*(1+SUMIFS(Assumptions!$C:$C,Assumptions!$A:$A,$F6,Assumptions!$B:$B,"High"))*SUMIFS(Assumptions!$E:$E,Assumptions!$A:$A,$F6,Assumptions!$B:$B,"High")*SUMIFS(Assumptions!$J:$J,Assumptions!$A:$A,$F6,Assumptions!$B:$B,"High")))*(1+SUMIFS(Assumptions!$D:$D,Assumptions!$A:$A,$F6,Assumptions!$B:$B,"High"))*SUMIFS(Assumptions!$E:$E,Assumptions!$A:$A,$F6,Assumptions!$B:$B,"High")*SUMIFS(Assumptions!$G:$G,Assumptions!$A:$A,$F6,Assumptions!$B:$B,"High")*SUMIFS(Assumptions!$I:$I,Assumptions!$A:$A,$F6,Assumptions!$B:$B,"High"))-(((SUMIFS(Raw_Data!$D:$D,Raw_Data!$A:$A,$F6)*(1+SUMIFS(Assumptions!$C:$C,Assumptions!$A:$A,$F6,Assumptions!$B:$B,"High"))+(SUMIFS(Raw_Data!$D:$D,Raw_Data!$A:$A,$F6)*(1+SUMIFS(Assumptions!$C:$C,Assumptions!$A:$A,$F6,Assumptions!$B:$B,"High"))*SUMIFS(Assumptions!$E:$E,Assumptions!$A:$A,$F6,Assumptions!$B:$B,"High")*SUMIFS(Assumptions!$F:$F,Assumptions!$A:$A,$F6,Assumptions!$B:$B,"High")*SUMIFS(Assumptions!$H:$H,Assumptions!$A:$A,$F6,Assumptions!$B:$B,"High"))-(SUMIFS(Raw_Data!$D:$D,Raw_Data!$A:$A,$F6)*(1+SUMIFS(Assumptions!$C:$C,Assumptions!$A:$A,$F6,Assumptions!$B:$B,"High"))*SUMIFS(Assumptions!$E:$E,Assumptions!$A:$A,$F6,Assumptions!$B:$B,"High")*SUMIFS(Assumptions!$J:$J,Assumptions!$A:$A,$F6,Assumptions!$B:$B,"High")))*(1+SUMIFS(Assumptions!$D:$D,Assumptions!$A:$A,$F6,Assumptions!$B:$B,"High"))*SUMIFS(Assumptions!$E:$E,Assumptions!$A:$A,$F6,Assumptions!$B:$B,"High")*SUMIFS(Assumptions!$K:$K,Assumptions!$A:$A,$F6,Assumptions!$B:$B,"High"))))) -> 47.862998 | K6: Salesforce | L6: =Scenario_Model!R6 -> 0.59422589 | M6: =Scenario_Model!T6 -> 0.1613283 | O6: Salesforce | P6: =Revenue_Mix!B6 -> 0.023749835 | Q6: =Revenue_Mix!F6 -> 0.044408652
A7: Adobe | B7: =Scenario_Model!B7 -> 23.769 | C7: =Scenario_Model!U7 -> 28.740835 | D7: =Revenue_Mix!F7 -> 0.015546656 | F7: Adobe | G7: =((SUMIFS(Raw_Data!$D:$D,Raw_Data!$A:$A,$F7)*(1+SUMIFS(Assumptions!$C:$C,Assumptions!$A:$A,$F7,Assumptions!$B:$B,"Low"))+(SUMIFS(Raw_Data!$D:$D,Raw_Data!$A:$A,$F7)*(1+SUMIFS(Assumptions!$C:$C,Assumptions!$A:$A,$F7,Assumptions!$B:$B,"Low"))*SUMIFS(Assumptions!$E:$E,Assumptions!$A:$A,$F7,Assumptions!$B:$B,"Low")*SUMIFS(Assumptions!$F:$F,Assumptions!$A:$A,$F7,Assumptions!$B:$B,"Low")*SUMIFS(Assumptions!$H:$H,Assumptions!$A:$A,$F7,Assumptions!$B:$B,"Low"))-(SUMIFS(Raw_Data!$D:$D,Raw_Data!$A:$A,$F7)*(1+SUMIFS(Assumptions!$C:$C,Assumptions!$A:$A,$F7,Assumptions!$B:$B,"Low"))*SUMIFS(Assumptions!$E:$E,Assumptions!$A:$A,$F7,Assumptions!$B:$B,"Low")*SUMIFS(Assumptions!$J:$J,Assumptions!$A:$A,$F7,Assumptions!$B:$B,"Low")))*(1+SUMIFS(Assumptions!$D:$D,Assumptions!$A:$A,$F7,Assumptions!$B:$B,"Low"))+(((SUMIFS(Raw_Data!$D:$D,Raw_Data!$A:$A,$F7)*(1+SUMIFS(Assumptions!$C:$C,Assumptions!$A:$A,$F7,Assumptions!$B:$B,"Low"))+(SUMIFS(Raw_Data!$D:$D,Raw_Data!$A:$A,$F7)*(1+SUMIFS(Assumptions!$C:$C,Assumptions!$A:$A,$F7,Assumptions!$B:$B,"Low"))*SUMIFS(Assumptions!$E:$E,Assumptions!$A:$A,$F7,Assumptions!$B:$B,"Low")*SUMIFS(Assumptions!$F:$F,Assumptions!$A:$A,$F7,Assumptions!$B:$B,"Low")*SUMIFS(Assumptions!$H:$H,Assumptions!$A:$A,$F7,Assumptions!$B:$B,"Low"))-(SUMIFS(Raw_Data!$D:$D,Raw_Data!$A:$A,$F7)*(1+SUMIFS(Assumptions!$C:$C,Assumptions!$A:$A,$F7,Assumptions!$B:$B,"Low"))*SUMIFS(Assumptions!$E:$E,Assumptions!$A:$A,$F7,Assumptions!$B:$B,"Low")*SUMIFS(Assumptions!$J:$J,Assumptions!$A:$A,$F7,Assumptions!$B:$B,"Low")))*(1+SUMIFS(Assumptions!$D:$D,Assumptions!$A:$A,$F7,Assumptions!$B:$B,"Low"))*SUMIFS(Assumptions!$E:$E,Assumptions!$A:$A,$F7,Assumptions!$B:$B,"Low")*SUMIFS(Assumptions!$G:$G,Assumptions!$A:$A,$F7,Assumptions!$B:$B,"Low")*SUMIFS(Assumptions!$I:$I,Assumptions!$A:$A,$F7,Assumptions!$B:$B,"Low"))-(((SUMIFS(Raw_Data!$D:$D,Raw_Data!$A:$A,$F7)*(1+SUMIFS(Assumptions!$C:$C,Assumptions!$A:$A,$F7,Assumptions!$B:$B,"Low"))+(SUMIFS(Raw_Data!$D:$D,Raw_Data!$A:$A,$F7)*(1+SUMIFS(Assumptions!$C:$C,Assumptions!$A:$A,$F7,Assumptions!$B:$B,"Low"))*SUMIFS(Assumptions!$E:$E,Assumptions!$A:$A,$F7,Assumptions!$B:$B,"Low")*SUMIFS(Assumptions!$F:$F,Assumptions!$A:$A,$F7,Assumptions!$B:$B,"Low")*SUMIFS(Assumptions!$H:$H,Assumptions!$A:$A,$F7,Assumptions!$B:$B,"Low"))-(SUMIFS(Raw_Data!$D:$D,Raw_Data!$A:$A,$F7)*(1+SUMIFS(Assumptions!$C:$C,Assumptions!$A:$A,$F7,Assumptions!$B:$B,"Low"))*SUMIFS(Assumptions!$E:$E,Assumptions!$A:$A,$F7,Assumptions!$B:$B,"Low")*SUMIFS(Assumptions!$J:$J,Assumptions!$A:$A,$F7,Assumptions!$B:$B,"Low")))*(1+SUMIFS(Assumptions!$D:$D,Assumptions!$A:$A,$F7,Assumptions!$B:$B,"Low"))*SUMIFS(Assumptions!$E:$E,Assumptions!$A:$A,$F7,Assumptions!$B:$B,"Low")*SUMIFS(Assumptions!$K:$K,Assumptions!$A:$A,$F7,Assumptions!$B:$B,"Low"))))) -> 27.497671 | H7: =((SUMIFS(Raw_Data!$D:$D,Raw_Data!$A:$A,$F7)*(1+SUMIFS(Assumptions!$C:$C,Assumptions!$A:$A,$F7,Assumptions!$B:$B,"Base"))+(SUMIFS(Raw_Data!$D:$D,Raw_Data!$A:$A,$F7)*(1+SUMIFS(Assumptions!$C:$C,Assumptions!$A:$A,$F7,Assumptions!$B:$B,"Base"))*SUMIFS(Assumptions!$E:$E,Assumptions!$A:$A,$F7,Assumptions!$B:$B,"Base")*SUMIFS(Assumptions!$F:$F,Assumptions!$A:$A,$F7,Assumptions!$B:$B,"Base")*SUMIFS(Assumptions!$H:$H,Assumptions!$A:$A,$F7,Assumptions!$B:$B,"Base"))-(SUMIFS(Raw_Data!$D:$D,Raw_Data!$A:$A,$F7)*(1+SUMIFS(Assumptions!$C:$C,Assumptions!$A:$A,$F7,Assumptions!$B:$B,"Base"))*SUMIFS(Assumptions!$E:$E,Assumptions!$A:$A,$F7,Assumptions!$B:$B,"Base")*SUMIFS(Assumptions!$J:$J,Assumptions!$A:$A,$F7,Assumptions!$B:$B,"Base")))*(1+SUMIFS(Assumptions!$D:$D,Assumptions!$A:$A,$F7,Assumptions!$B:$B,"Base"))+(((SUMIFS(Raw_Data!$D:$D,Raw_Data!$A:$A,$F7)*(1+SUMIFS(Assumptions!$C:$C,Assumptions!$A:$A,$F7,Assumptions!$B:$B,"Base"))+(SUMIFS(Raw_Data!$D:$D,Raw_Data!$A:$A,$F7)*(1+SUMIFS(Assumptions!$C:$C,Assumptions!$A:$A,$F7,Assumptions!$B:$B,"Base"))*SUMIFS(Assumptions!$E:$E,Assumptions!$A:$A,$F7,Assumptions!$B:$B,"Base")*SUMIFS(Assumptions!$F:$F,Assumptions!$A:$A,$F7,Assumptions!$B:$B,"Base")*SUMIFS(Assumptions!$H:$H,Assumptions!$A:$A,$F7,Assumptions!$B:$B,"Base"))-(SUMIFS(Raw_Data!$D:$D,Raw_Data!$A:$A,$F7)*(1+SUMIFS(Assumptions!$C:$C,Assumptions!$A:$A,$F7,Assumptions!$B:$B,"Base"))*SUMIFS(Assumptions!$E:$E,Assumptions!$A:$A,$F7,Assumptions!$B:$B,"Base")*SUMIFS(Assumptions!$J:$J,Assumptions!$A:$A,$F7,Assumptions!$B:$B,"Base")))*(1+SUMIFS(Assumptions!$D:$D,Assumptions!$A:$A,$F7,Assumptions!$B:$B,"Base"))*SUMIFS(Assumptions!$E:$E,Assumptions!$A:$A,$F7,Assumptions!$B:$B,"Base")*SUMIFS(Assumptions!$G:$G,Assumptions!$A:$A,$F7,Assumptions!$B:$B,"Base")*SUMIFS(Assumptions!$I:$I,Assumptions!$A:$A,$F7,Assumptions!$B:$B,"Base"))-(((SUMIFS(Raw_Data!$D:$D,Raw_Data!$A:$A,$F7)*(1+SUMIFS(Assumptions!$C:$C,Assumptions!$A:$A,$F7,Assumptions!$B:$B,"Base"))+(SUMIFS(Raw_Data!$D:$D,Raw_Data!$A:$A,$F7)*(1+SUMIFS(Assumptions!$C:$C,Assumptions!$A:$A,$F7,Assumptions!$B:$B,"Base"))*SUMIFS(Assumptions!$E:$E,Assumptions!$A:$A,$F7,Assumptions!$B:$B,"Base")*SUMIFS(Assumptions!$F:$F,Assumptions!$A:$A,$F7,Assumptions!$B:$B,"Base")*SUMIFS(Assumptions!$H:$H,Assumptions!$A:$A,$F7,Assumptions!$B:$B,"Base"))-(SUMIFS(Raw_Data!$D:$D,Raw_Data!$A:$A,$F7)*(1+SUMIFS(Assumptions!$C:$C,Assumptions!$A:$A,$F7,Assumptions!$B:$B,"Base"))*SUMIFS(Assumptions!$E:$E,Assumptions!$A:$A,$F7,Assumptions!$B:$B,"Base")*SUMIFS(Assumptions!$J:$J,Assumptions!$A:$A,$F7,Assumptions!$B:$B,"Base")))*(1+SUMIFS(Assumptions!$D:$D,Assumptions!$A:$A,$F7,Assumptions!$B:$B,"Base"))*SUMIFS(Assumptions!$E:$E,Assumptions!$A:$A,$F7,Assumptions!$B:$B,"Base")*SUMIFS(Assumptions!$K:$K,Assumptions!$A:$A,$F7,Assumptions!$B:$B,"Base"))))) -> 28.740835 | I7: =((SUMIFS(Raw_Data!$D:$D,Raw_Data!$A:$A,$F7)*(1+SUMIFS(Assumptions!$C:$C,Assumptions!$A:$A,$F7,Assumptions!$B:$B,"High"))+(SUMIFS(Raw_Data!$D:$D,Raw_Data!$A:$A,$F7)*(1+SUMIFS(Assumptions!$C:$C,Assumptions!$A:$A,$F7,Assumptions!$B:$B,"High"))*SUMIFS(Assumptions!$E:$E,Assumptions!$A:$A,$F7,Assumptions!$B:$B,"High")*SUMIFS(Assumptions!$F:$F,Assumptions!$A:$A,$F7,Assumptions!$B:$B,"High")*SUMIFS(Assumptions!$H:$H,Assumptions!$A:$A,$F7,Assumptions!$B:$B,"High"))-(SUMIFS(Raw_Data!$D:$D,Raw_Data!$A:$A,$F7)*(1+SUMIFS(Assumptions!$C:$C,Assumptions!$A:$A,$F7,Assumptions!$B:$B,"High"))*SUMIFS(Assumptions!$E:$E,Assumptions!$A:$A,$F7,Assumptions!$B:$B,"High")*SUMIFS(Assumptions!$J:$J,Assumptions!$A:$A,$F7,Assumptions!$B:$B,"High")))*(1+SUMIFS(Assumptions!$D:$D,Assumptions!$A:$A,$F7,Assumptions!$B:$B,"High"))+(((SUMIFS(Raw_Data!$D:$D,Raw_Data!$A:$A,$F7)*(1+SUMIFS(Assumptions!$C:$C,Assumptions!$A:$A,$F7,Assumptions!$B:$B,"High"))+(SUMIFS(Raw_Data!$D:$D,Raw_Data!$A:$A,$F7)*(1+SUMIFS(Assumptions!$C:$C,Assumptions!$A:$A,$F7,Assumptions!$B:$B,"High"))*SUMIFS(Assumptions!$E:$E,Assumptions!$A:$A,$F7,Assumptions!$B:$B,"High")*SUMIFS(Assumptions!$F:$F,Assumptions!$A:$A,$F7,Assumptions!$B:$B,"High")*SUMIFS(Assumptions!$H:$H,Assumptions!$A:$A,$F7,Assumptions!$B:$B,"High"))-(SUMIFS(Raw_Data!$D:$D,Raw_Data!$A:$A,$F7)*(1+SUMIFS(Assumptions!$C:$C,Assumptions!$A:$A,$F7,Assumptions!$B:$B,"High"))*SUMIFS(Assumptions!$E:$E,Assumptions!$A:$A,$F7,Assumptions!$B:$B,"High")*SUMIFS(Assumptions!$J:$J,Assumptions!$A:$A,$F7,Assumptions!$B:$B,"High")))*(1+SUMIFS(Assumptions!$D:$D,Assumptions!$A:$A,$F7,Assumptions!$B:$B,"High"))*SUMIFS(Assumptions!$E:$E,Assumptions!$A:$A,$F7,Assumptions!$B:$B,"High")*SUMIFS(Assumptions!$G:$G,Assumptions!$A:$A,$F7,Assumptions!$B:$B,"High")*SUMIFS(Assumptions!$I:$I,Assumptions!$A:$A,$F7,Assumptions!$B:$B,"High"))-(((SUMIFS(Raw_Data!$D:$D,Raw_Data!$A:$A,$F7)*(1+SUMIFS(Assumptions!$C:$C,Assumptions!$A:$A,$F7,Assumptions!$B:$B,"High"))+(SUMIFS(Raw_Data!$D:$D,Raw_Data!$A:$A,$F7)*(1+SUMIFS(Assumptions!$C:$C,Assumptions!$A:$A,$F7,Assumptions!$B:$B,"High"))*SUMIFS(Assumptions!$E:$E,Assumptions!$A:$A,$F7,Assumptions!$B:$B,"High")*SUMIFS(Assumptions!$F:$F,Assumptions!$A:$A,$F7,Assumptions!$B:$B,"High")*SUMIFS(Assumptions!$H:$H,Assumptions!$A:$A,$F7,Assumptions!$B:$B,"High"))-(SUMIFS(Raw_Data!$D:$D,Raw_Data!$A:$A,$F7)*(1+SUMIFS(Assumptions!$C:$C,Assumptions!$A:$A,$F7,Assumptions!$B:$B,"High"))*SUMIFS(Assumptions!$E:$E,Assumptions!$A:$A,$F7,Assumptions!$B:$B,"High")*SUMIFS(Assumptions!$J:$J,Assumptions!$A:$A,$F7,Assumptions!$B:$B,"High")))*(1+SUMIFS(Assumptions!$D:$D,Assumptions!$A:$A,$F7,Assumptions!$B:$B,"High"))*SUMIFS(Assumptions!$E:$E,Assumptions!$A:$A,$F7,Assumptions!$B:$B,"High")*SUMIFS(Assumptions!$K:$K,Assumptions!$A:$A,$F7,Assumptions!$B:$B,"High"))))) -> 30.219565 | K7: Adobe | L7: =Scenario_Model!R7 -> 0.28282319 | M7: =Scenario_Model!T7 -> 0.10998679 | O7: Adobe | P7: =Revenue_Mix!B7 -> 0 | Q7: =Revenue_Mix!F7 -> 0.015546656
A8: ServiceNow | B8: =Scenario_Model!B8 -> 10.984 | C8: =Scenario_Model!U8 -> 16.088344 | D8: =Revenue_Mix!F8 -> 0.039375136 | F8: ServiceNow | G8: =((SUMIFS(Raw_Data!$D:$D,Raw_Data!$A:$A,$F8)*(1+SUMIFS(Assumptions!$C:$C,Assumptions!$A:$A,$F8,Assumptions!$B:$B,"Low"))+(SUMIFS(Raw_Data!$D:$D,Raw_Data!$A:$A,$F8)*(1+SUMIFS(Assumptions!$C:$C,Assumptions!$A:$A,$F8,Assumptions!$B:$B,"Low"))*SUMIFS(Assumptions!$E:$E,Assumptions!$A:$A,$F8,Assumptions!$B:$B,"Low")*SUMIFS(Assumptions!$F:$F,Assumptions!$A:$A,$F8,Assumptions!$B:$B,"Low")*SUMIFS(Assumptions!$H:$H,Assumptions!$A:$A,$F8,Assumptions!$B:$B,"Low"))-(SUMIFS(Raw_Data!$D:$D,Raw_Data!$A:$A,$F8)*(1+SUMIFS(Assumptions!$C:$C,Assumptions!$A:$A,$F8,Assumptions!$B:$B,"Low"))*SUMIFS(Assumptions!$E:$E,Assumptions!$A:$A,$F8,Assumptions!$B:$B,"Low")*SUMIFS(Assumptions!$J:$J,Assumptions!$A:$A,$F8,Assumptions!$B:$B,"Low")))*(1+SUMIFS(Assumptions!$D:$D,Assumptions!$A:$A,$F8,Assumptions!$B:$B,"Low"))+(((SUMIFS(Raw_Data!$D:$D,Raw_Data!$A:$A,$F8)*(1+SUMIFS(Assumptions!$C:$C,Assumptions!$A:$A,$F8,Assumptions!$B:$B,"Low"))+(SUMIFS(Raw_Data!$D:$D,Raw_Data!$A:$A,$F8)*(1+SUMIFS(Assumptions!$C:$C,Assumptions!$A:$A,$F8,Assumptions!$B:$B,"Low"))*SUMIFS(Assumptions!$E:$E,Assumptions!$A:$A,$F8,Assumptions!$B:$B,"Low")*SUMIFS(Assumptions!$F:$F,Assumptions!$A:$A,$F8,Assumptions!$B:$B,"Low")*SUMIFS(Assumptions!$H:$H,Assumptions!$A:$A,$F8,Assumptions!$B:$B,"Low"))-(SUMIFS(Raw_Data!$D:$D,Raw_Data!$A:$A,$F8)*(1+SUMIFS(Assumptions!$C:$C,Assumptions!$A:$A,$F8,Assumptions!$B:$B,"Low"))*SUMIFS(Assumptions!$E:$E,Assumptions!$A:$A,$F8,Assumptions!$B:$B,"Low")*SUMIFS(Assumptions!$J:$J,Assumptions!$A:$A,$F8,Assumptions!$B:$B,"Low")))*(1+SUMIFS(Assumptions!$D:$D,Assumptions!$A:$A,$F8,Assumptions!$B:$B,"Low"))*SUMIFS(Assumptions!$E:$E,Assumptions!$A:$A,$F8,Assumptions!$B:$B,"Low")*SUMIFS(Assumptions!$G:$G,Assumptions!$A:$A,$F8,Assumptions!$B:$B,"Low")*SUMIFS(Assumptions!$I:$I,Assumptions!$A:$A,$F8,Assumptions!$B:$B,"Low"))-(((SUMIFS(Raw_Data!$D:$D,Raw_Data!$A:$A,$F8)*(1+SUMIFS(Assumptions!$C:$C,Assumptions!$A:$A,$F8,Assumptions!$B:$B,"Low"))+(SUMIFS(Raw_Data!$D:$D,Raw_Data!$A:$A,$F8)*(1+SUMIFS(Assumptions!$C:$C,Assumptions!$A:$A,$F8,Assumptions!$B:$B,"Low"))*SUMIFS(Assumptions!$E:$E,Assumptions!$A:$A,$F8,Assumptions!$B:$B,"Low")*SUMIFS(Assumptions!$F:$F,Assumptions!$A:$A,$F8,Assumptions!$B:$B,"Low")*SUMIFS(Assumptions!$H:$H,Assumptions!$A:$A,$F8,Assumptions!$B:$B,"Low"))-(SUMIFS(Raw_Data!$D:$D,Raw_Data!$A:$A,$F8)*(1+SUMIFS(Assumptions!$C:$C,Assumptions!$A:$A,$F8,Assumptions!$B:$B,"Low"))*SUMIFS(Assumptions!$E:$E,Assumptions!$A:$A,$F8,Assumptions!$B:$B,"Low")*SUMIFS(Assumptions!$J:$J,Assumptions!$A:$A,$F8,Assumptions!$B:$B,"Low")))*(1+SUMIFS(Assumptions!$D:$D,Assumptions!$A:$A,$F8,Assumptions!$B:$B,"Low"))*SUMIFS(Assumptions!$E:$E,Assumptions!$A:$A,$F8,Assumptions!$B:$B,"Low")*SUMIFS(Assumptions!$K:$K,Assumptions!$A:$A,$F8,Assumptions!$B:$B,"Low"))))) -> 15.095845 | H8: =((SUMIFS(Raw_Data!$D:$D,Raw_Data!$A:$A,$F8)*(1+SUMIFS(Assumptions!$C:$C,Assumptions!$A:$A,$F8,Assumptions!$B:$B,"Base"))+(SUMIFS(Raw_Data!$D:$D,Raw_Data!$A:$A,$F8)*(1+SUMIFS(Assumptions!$C:$C,Assumptions!$A:$A,$F8,Assumptions!$B:$B,"Base"))*SUMIFS(Assumptions!$E:$E,Assumptions!$A:$A,$F8,Assumptions!$B:$B,"Base")*SUMIFS(Assumptions!$F:$F,Assumptions!$A:$A,$F8,Assumptions!$B:$B,"Base")*SUMIFS(Assumptions!$H:$H,Assumptions!$A:$A,$F8,Assumptions!$B:$B,"Base"))-(SUMIFS(Raw_Data!$D:$D,Raw_Data!$A:$A,$F8)*(1+SUMIFS(Assumptions!$C:$C,Assumptions!$A:$A,$F8,Assumptions!$B:$B,"Base"))*SUMIFS(Assumptions!$E:$E,Assumptions!$A:$A,$F8,Assumptions!$B:$B,"Base")*SUMIFS(Assumptions!$J:$J,Assumptions!$A:$A,$F8,Assumptions!$B:$B,"Base")))*(1+SUMIFS(Assumptions!$D:$D,Assumptions!$A:$A,$F8,Assumptions!$B:$B,"Base"))+(((SUMIFS(Raw_Data!$D:$D,Raw_Data!$A:$A,$F8)*(1+SUMIFS(Assumptions!$C:$C,Assumptions!$A:$A,$F8,Assumptions!$B:$B,"Base"))+(SUMIFS(Raw_Data!$D:$D,Raw_Data!$A:$A,$F8)*(1+SUMIFS(Assumptions!$C:$C,Assumptions!$A:$A,$F8,Assumptions!$B:$B,"Base"))*SUMIFS(Assumptions!$E:$E,Assumptions!$A:$A,$F8,Assumptions!$B:$B,"Base")*SUMIFS(Assumptions!$F:$F,Assumptions!$A:$A,$F8,Assumptions!$B:$B,"Base")*SUMIFS(Assumptions!$H:$H,Assumptions!$A:$A,$F8,Assumptions!$B:$B,"Base"))-(SUMIFS(Raw_Data!$D:$D,Raw_Data!$A:$A,$F8)*(1+SUMIFS(Assumptions!$C:$C,Assumptions!$A:$A,$F8,Assumptions!$B:$B,"Base"))*SUMIFS(Assumptions!$E:$E,Assumptions!$A:$A,$F8,Assumptions!$B:$B,"Base")*SUMIFS(Assumptions!$J:$J,Assumptions!$A:$A,$F8,Assumptions!$B:$B,"Base")))*(1+SUMIFS(Assumptions!$D:$D,Assumptions!$A:$A,$F8,Assumptions!$B:$B,"Base"))*SUMIFS(Assumptions!$E:$E,Assumptions!$A:$A,$F8,Assumptions!$B:$B,"Base")*SUMIFS(Assumptions!$G:$G,Assumptions!$A:$A,$F8,Assumptions!$B:$B,"Base")*SUMIFS(Assumptions!$I:$I,Assumptions!$A:$A,$F8,Assumptions!$B:$B,"Base"))-(((SUMIFS(Raw_Data!$D:$D,Raw_Data!$A:$A,$F8)*(1+SUMIFS(Assumptions!$C:$C,Assumptions!$A:$A,$F8,Assumptions!$B:$B,"Base"))+(SUMIFS(Raw_Data!$D:$D,Raw_Data!$A:$A,$F8)*(1+SUMIFS(Assumptions!$C:$C,Assumptions!$A:$A,$F8,Assumptions!$B:$B,"Base"))*SUMIFS(Assumptions!$E:$E,Assumptions!$A:$A,$F8,Assumptions!$B:$B,"Base")*SUMIFS(Assumptions!$F:$F,Assumptions!$A:$A,$F8,Assumptions!$B:$B,"Base")*SUMIFS(Assumptions!$H:$H,Assumptions!$A:$A,$F8,Assumptions!$B:$B,"Base"))-(SUMIFS(Raw_Data!$D:$D,Raw_Data!$A:$A,$F8)*(1+SUMIFS(Assumptions!$C:$C,Assumptions!$A:$A,$F8,Assumptions!$B:$B,"Base"))*SUMIFS(Assumptions!$E:$E,Assumptions!$A:$A,$F8,Assumptions!$B:$B,"Base")*SUMIFS(Assumptions!$J:$J,Assumptions!$A:$A,$F8,Assumptions!$B:$B,"Base")))*(1+SUMIFS(Assumptions!$D:$D,Assumptions!$A:$A,$F8,Assumptions!$B:$B,"Base"))*SUMIFS(Assumptions!$E:$E,Assumptions!$A:$A,$F8,Assumptions!$B:$B,"Base")*SUMIFS(Assumptions!$K:$K,Assumptions!$A:$A,$F8,Assumptions!$B:$B,"Base"))))) -> 16.088344 | I8: =((SUMIFS(Raw_Data!$D:$D,Raw_Data!$A:$A,$F8)*(1+SUMIFS(Assumptions!$C:$C,Assumptions!$A:$A,$F8,Assumptions!$B:$B,"High"))+(SUMIFS(Raw_Data!$D:$D,Raw_Data!$A:$A,$F8)*(1+SUMIFS(Assumptions!$C:$C,Assumptions!$A:$A,$F8,Assumptions!$B:$B,"High"))*SUMIFS(Assumptions!$E:$E,Assumptions!$A:$A,$F8,Assumptions!$B:$B,"High")*SUMIFS(Assumptions!$F:$F,Assumptions!$A:$A,$F8,Assumptions!$B:$B,"High")*SUMIFS(Assumptions!$H:$H,Assumptions!$A:$A,$F8,Assumptions!$B:$B,"High"))-(SUMIFS(Raw_Data!$D:$D,Raw_Data!$A:$A,$F8)*(1+SUMIFS(Assumptions!$C:$C,Assumptions!$A:$A,$F8,Assumptions!$B:$B,"High"))*SUMIFS(Assumptions!$E:$E,Assumptions!$A:$A,$F8,Assumptions!$B:$B,"High")*SUMIFS(Assumptions!$J:$J,Assumptions!$A:$A,$F8,Assumptions!$B:$B,"High")))*(1+SUMIFS(Assumptions!$D:$D,Assumptions!$A:$A,$F8,Assumptions!$B:$B,"High"))+(((SUMIFS(Raw_Data!$D:$D,Raw_Data!$A:$A,$F8)*(1+SUMIFS(Assumptions!$C:$C,Assumptions!$A:$A,$F8,Assumptions!$B:$B,"High"))+(SUMIFS(Raw_Data!$D:$D,Raw_Data!$A:$A,$F8)*(1+SUMIFS(Assumptions!$C:$C,Assumptions!$A:$A,$F8,Assumptions!$B:$B,"High"))*SUMIFS(Assumptions!$E:$E,Assumptions!$A:$A,$F8,Assumptions!$B:$B,"High")*SUMIFS(Assumptions!$F:$F,Assumptions!$A:$A,$F8,Assumptions!$B:$B,"High")*SUMIFS(Assumptions!$H:$H,Assumptions!$A:$A,$F8,Assumptions!$B:$B,"High"))-(SUMIFS(Raw_Data!$D:$D,Raw_Data!$A:$A,$F8)*(1+SUMIFS(Assumptions!$C:$C,Assumptions!$A:$A,$F8,Assumptions!$B:$B,"High"))*SUMIFS(Assumptions!$E:$E,Assumptions!$A:$A,$F8,Assumptions!$B:$B,"High")*SUMIFS(Assumptions!$J:$J,Assumptions!$A:$A,$F8,Assumptions!$B:$B,"High")))*(1+SUMIFS(Assumptions!$D:$D,Assumptions!$A:$A,$F8,Assumptions!$B:$B,"High"))*SUMIFS(Assumptions!$E:$E,Assumptions!$A:$A,$F8,Assumptions!$B:$B,"High")*SUMIFS(Assumptions!$G:$G,Assumptions!$A:$A,$F8,Assumptions!$B:$B,"High")*SUMIFS(Assumptions!$I:$I,Assumptions!$A:$A,$F8,Assumptions!$B:$B,"High"))-(((SUMIFS(Raw_Data!$D:$D,Raw_Data!$A:$A,$F8)*(1+SUMIFS(Assumptions!$C:$C,Assumptions!$A:$A,$F8,Assumptions!$B:$B,"High"))+(SUMIFS(Raw_Data!$D:$D,Raw_Data!$A:$A,$F8)*(1+SUMIFS(Assumptions!$C:$C,Assumptions!$A:$A,$F8,Assumptions!$B:$B,"High"))*SUMIFS(Assumptions!$E:$E,Assumptions!$A:$A,$F8,Assumptions!$B:$B,"High")*SUMIFS(Assumptions!$F:$F,Assumptions!$A:$A,$F8,Assumptions!$B:$B,"High")*SUMIFS(Assumptions!$H:$H,Assumptions!$A:$A,$F8,Assumptions!$B:$B,"High"))-(SUMIFS(Raw_Data!$D:$D,Raw_Data!$A:$A,$F8)*(1+SUMIFS(Assumptions!$C:$C,Assumptions!$A:$A,$F8,Assumptions!$B:$B,"High"))*SUMIFS(Assumptions!$E:$E,Assumptions!$A:$A,$F8,Assumptions!$B:$B,"High")*SUMIFS(Assumptions!$J:$J,Assumptions!$A:$A,$F8,Assumptions!$B:$B,"High")))*(1+SUMIFS(Assumptions!$D:$D,Assumptions!$A:$A,$F8,Assumptions!$B:$B,"High"))*SUMIFS(Assumptions!$E:$E,Assumptions!$A:$A,$F8,Assumptions!$B:$B,"High")*SUMIFS(Assumptions!$K:$K,Assumptions!$A:$A,$F8,Assumptions!$B:$B,"High"))))) -> 17.26457 | K8: ServiceNow | L8: =Scenario_Model!R8 -> 0.21103955 | M8: =Scenario_Model!T8 -> 0.038197204 | O8: ServiceNow | P8: =Revenue_Mix!B8 -> 0.018208303 | Q8: =Revenue_Mix!F8 -> 0.039375136
